Workbook

Sheet Planner
A1: CENTERBEAM LUMBER CAR LAYOUT PLANNER — 72 ft
A2: Inventory is a line-item tally: each line = Product + Length + Grade + Packs. Cell FILL = product, BORDER = grade. Each car row totals exactly 72 ft. Example loaded.
A4: CONFIGURATION
A5: Number of Rows: | C5: 10
A6: Row Capacity (ft): | C6: 72
A8: LUMBER INVENTORY — line-item tally (Product × Length × Grade)
A9: # | B9: Product | C9: Length | D9: Grade | E9: Packs | F9: Lineal | G9: Placed | H9: Remain | J9: LOAD STATUS
A10: 1 | B10: 2x4 | C10: 16 | D10: 2 | E10: 2 | F10: =IF(B10="","",C10*E10) -> 32 | G10: =IF(B10="","",COUNTIF($B$34:$J$47,B10&"-"&C10&"-"&D10)) -> 2 | H10: =IF(B10="","",E10-G10) -> 0 | I10: =IF(B10="",0,C10*G10) -> 32 | J10: Total Lineal Ft: | L10: =F30 -> 720
A11: 2 | B11: 2x6 | C11: 16 | D11: 2 | E11: 3 | F11: =IF(B11="","",C11*E11) -> 48 | G11: =IF(B11="","",COUNTIF($B$34:$J$47,B11&"-"&C11&"-"&D11)) -> 3 | H11: =IF(B11="","",E11-G11) -> 0 | I11: =IF(B11="",0,C11*G11) -> 48 | J11: Car Capacity (ft): | L11: =C5*C6 -> 720
A12: 3 | B12: 2x6 | C12: 14 | D12: 2 | E12: 12 | F12: =IF(B12="","",C12*E12) -> 168 | G12: =IF(B12="","",COUNTIF($B$34:$J$47,B12&"-"&C12&"-"&D12)) -> 12 | H12: =IF(B12="","",E12-G12) -> 0 | I12: =IF(B12="",0,C12*G12) -> 168 | J12: Difference: | L12: =F30-C5*C6 -> 0
A13: 4 | B13: 2x8 | C13: 14 | D13: MSR | E13: 8 | F13: =IF(B13="","",C13*E13) -> 112 | G13: =IF(B13="","",COUNTIF($B$34:$J$47,B13&"-"&C13&"-"&D13)) -> 8 | H13: =IF(B13="","",E13-G13) -> 0 | I13: =IF(B13="",0,C13*G13) -> 112 | J13: Rows Needed: | L13: =IF(F30=0,0,ROUNDUP(F30/C6,0)) -> 10
A14: 5 | B14: 2x4 | C14: 12 | D14: 1 | E14: 30 | F14: =IF(B14="","",C14*E14) -> 360 | G14: =IF(B14="","",COUNTIF($B$34:$J$47,B14&"-"&C14&"-"&D14)) -> 30 | H14: =IF(B14="","",E14-G14) -> 0 | I14: =IF(B14="",0,C14*G14) -> 360 | J14: Rows OK (=72): | L14: =COUNTIF($L$34:$L$47,"OK 72") -> 10
A15: 6 | F15: =IF(B15="","",C15*E15) | G15: =IF(B15="","",COUNTIF($B$34:$J$47,B15&"-"&C15&"-"&D15)) | H15: =IF(B15="","",E15-G15) | I15: =IF(B15="",0,C15*G15) -> 0 | J15: Packs Placed: | L15: =COUNTA($B$34:$J$47) -> 55
A16: 7 | F16: =IF(B16="","",C16*E16) | G16: =IF(B16="","",COUNTIF($B$34:$J$47,B16&"-"&C16&"-"&D16)) | H16: =IF(B16="","",E16-G16) | I16: =IF(B16="",0,C16*G16) -> 0 | J16: Packs Unplaced: | L16: =E30-COUNTA($B$34:$J$47) -> 0
A17: 8 | F17: =IF(B17="","",C17*E17) | G17: =IF(B17="","",COUNTIF($B$34:$J$47,B17&"-"&C17&"-"&D17)) | H17: =IF(B17="","",E17-G17) | I17: =IF(B17="",0,C17*G17) -> 0 | J17: STATUS: | L17: =IF(E30-COUNTA($B$34:$J$47)>0,"OVERLOADED — "&(E30-COUNTA($B$34:$J$47))&" unplaced",IF(AND(COUNTIF($L$34:$L$47,"OK 72")=C5,C5>0),"PERFECT — all "&C5&" rows = 72ft",IF(COUNTIF($L$34:$L$47,"OVER*")>0,"ROW OVER 72 — fix","INCOMPLETE — keep filling"))) -> PERFECT — all 10 rows = 72ft
A18: 9 | F18: =IF(B18="","",C18*E18) | G18: =IF(B18="","",COUNTIF($B$34:$J$47,B18&"-"&C18&"-"&D18)) | H18: =IF(B18="","",E18-G18) | I18: =IF(B18="",0,C18*G18) -> 0
A19: 10 | F19: =IF(B19="","",C19*E19) | G19: =IF(B19="","",COUNTIF($B$34:$J$47,B19&"-"&C19&"-"&D19)) | H19: =IF(B19="","",E19-G19) | I19: =IF(B19="",0,C19*G19) -> 0
A20: 11 | F20: =IF(B20="","",C20*E20) | G20: =IF(B20="","",COUNTIF($B$34:$J$47,B20&"-"&C20&"-"&D20)) | H20: =IF(B20="","",E20-G20) | I20: =IF(B20="",0,C20*G20) -> 0
A21: 12 | F21: =IF(B21="","",C21*E21) | G21: =IF(B21="","",COUNTIF($B$34:$J$47,B21&"-"&C21&"-"&D21)) | H21: =IF(B21="","",E21-G21) | I21: =IF(B21="",0,C21*G21) -> 0
A22: 13 | F22: =IF(B22="","",C22*E22) | G22: =IF(B22="","",COUNTIF($B$34:$J$47,B22&"-"&C22&"-"&D22)) | H22: =IF(B22="","",E22-G22) | I22: =IF(B22="",0,C22*G22) -> 0
A23: 14 | F23: =IF(B23="","",C23*E23) | G23: =IF(B23="","",COUNTIF($B$34:$J$47,B23&"-"&C23&"-"&D23)) | H23: =IF(B23="","",E23-G23) | I23: =IF(B23="",0,C23*G23) -> 0
A24: 15 | F24: =IF(B24="","",C24*E24) | G24: =IF(B24="","",COUNTIF($B$34:$J$47,B24&"-"&C24&"-"&D24)) | H24: =IF(B24="","",E24-G24) | I24: =IF(B24="",0,C24*G24) -> 0
A25: 16 | F25: =IF(B25="","",C25*E25) | G25: =IF(B25="","",COUNTIF($B$34:$J$47,B25&"-"&C25&"-"&D25)) | H25: =IF(B25="","",E25-G25) | I25: =IF(B25="",0,C25*G25) -> 0
A26: 17 | F26: =IF(B26="","",C26*E26) | G26: =IF(B26="","",COUNTIF($B$34:$J$47,B26&"-"&C26&"-"&D26)) | H26: =IF(B26="","",E26-G26) | I26: =IF(B26="",0,C26*G26) -> 0
A27: 18 | F27: =IF(B27="","",C27*E27) | G27: =IF(B27="","",COUNTIF($B$34:$J$47,B27&"-"&C27&"-"&D27)) | H27: =IF(B27="","",E27-G27) | I27: =IF(B27="",0,C27*G27) -> 0
A28: 19 | F28: =IF(B28="","",C28*E28) | G28: =IF(B28="","",COUNTIF($B$34:$J$47,B28&"-"&C28&"-"&D28)) | H28: =IF(B28="","",E28-G28) | I28: =IF(B28="",0,C28*G28) -> 0
A29: 20 | F29: =IF(B29="","",C29*E29) | G29: =IF(B29="","",COUNTIF($B$34:$J$47,B29&"-"&C29&"-"&D29)) | H29: =IF(B29="","",E29-G29) | I29: =IF(B29="",0,C29*G29) -> 0
A30: TOTAL | E30: =SUM(E10:E29) -> 55 | F30: =SUM(F10:F29) -> 720 | G30: =SUM(G10:G29) -> 55 | H30: =SUM(H10:H29) -> 0 | I30: =SUM(I10:I29) -> 720
A32: LAYOUT GRID — product-length-grade per slot; each row = exactly 72 ft
A33: Row | B33: P1 | C33: P2 | D33: P3 | E33: P4 | F33: P5 | G33: P6 | H33: P7 | I33: P8 | J33: P9 | K33: Total | L33: Check
A34: R1 | B34: 2x4-16-2 | C34: 2x6-14-2 | D34: 2x6-14-2 | E34: 2x6-14-2 | F34: 2x6-14-2 | K34: =IFERROR(VALUE(MID(B34,FIND("-",B34)+1,FIND("-",B34,FIND("-",B34)+1)-FIND("-",B34)-1)),0)+IFERROR(VALUE(MID(C34,FIND("-",C34)+1,FIND("-",C34,FIND("-",C34)+1)-FIND("-",C34)-1)),0)+IFERROR(VALUE(MID(D34,FIND("-",D34)+1,FIND("-",D34,FIND("-",D34)+1)-FIND("-",D34)-1)),0)+IFERROR(VALUE(MID(E34,FIND("-",E34)+1,FIND("-",E34,FIND("-",E34)+1)-FIND("-",E34)-1)),0)+IFERROR(VALUE(MID(F34,FIND("-",F34)+1,FIND("-",F34,FIND("-",F34)+1)-FIND("-",F34)-1)),0)+IFERROR(VALUE(MID(G34,FIND("-",G34)+1,FIND("-",G34,FIND("-",G34)+1)-FIND("-",G34)-1)),0)+IFERROR(VALUE(MID(H34,FIND("-",H34)+1,FIND("-",H34,FIND("-",H34)+1)-FIND("-",H34)-1)),0)+IFERROR(VALUE(MID(I34,FIND("-",I34)+1,FIND("-",I34,FIND("-",I34)+1)-FIND("-",I34)-1)),0)+IFERROR(VALUE(MID(J34,FIND("-",J34)+1,FIND("-",J34,FIND("-",J34)+1)-FIND("-",J34)-1)),0) -> 72 | L34: =IF(ROW()-33>$C$5,"— unused —",IF(K34=0,"empty",IF(K34=$C$6,"OK 72",IF(K34>$C$6,"OVER "&K34,"SHORT "&($C$6-K34))))) -> OK 72
A35: R2 | B35: 2x4-16-2 | C35: 2x6-14-2 | D35: 2x6-14-2 | E35: 2x6-14-2 | F35: 2x6-14-2 | K35: =IFERROR(VALUE(MID(B35,FIND("-",B35)+1,FIND("-",B35,FIND("-",B35)+1)-FIND("-",B35)-1)),0)+IFERROR(VALUE(MID(C35,FIND("-",C35)+1,FIND("-",C35,FIND("-",C35)+1)-FIND("-",C35)-1)),0)+IFERROR(VALUE(MID(D35,FIND("-",D35)+1,FIND("-",D35,FIND("-",D35)+1)-FIND("-",D35)-1)),0)+IFERROR(VALUE(MID(E35,FIND("-",E35)+1,FIND("-",E35,FIND("-",E35)+1)-FIND("-",E35)-1)),0)+IFERROR(VALUE(MID(F35,FIND("-",F35)+1,FIND("-",F35,FIND("-",F35)+1)-FIND("-",F35)-1)),0)+IFERROR(VALUE(MID(G35,FIND("-",G35)+1,FIND("-",G35,FIND("-",G35)+1)-FIND("-",G35)-1)),0)+IFERROR(VALUE(MID(H35,FIND("-",H35)+1,FIND("-",H35,FIND("-",H35)+1)-FIND("-",H35)-1)),0)+IFERROR(VALUE(MID(I35,FIND("-",I35)+1,FIND("-",I35,FIND("-",I35)+1)-FIND("-",I35)-1)),0)+IFERROR(VALUE(MID(J35,FIND("-",J35)+1,FIND("-",J35,FIND("-",J35)+1)-FIND("-",J35)-1)),0) -> 72 | L35: =IF(ROW()-33>$C$5,"— unused —",IF(K35=0,"empty",IF(K35=$C$6,"OK 72",IF(K35>$C$6,"OVER "&K35,"SHORT "&($C$6-K35))))) -> OK 72
A36: R3 | B36: 2x6-16-2 | C36: 2x6-14-2 | D36: 2x6-14-2 | E36: 2x6-14-2 | F36: 2x6-14-2 | K36: =IFERROR(VALUE(MID(B36,FIND("-",B36)+1,FIND("-",B36,FIND("-",B36)+1)-FIND("-",B36)-1)),0)+IFERROR(VALUE(MID(C36,FIND("-",C36)+1,FIND("-",C36,FIND("-",C36)+1)-FIND("-",C36)-1)),0)+IFERROR(VALUE(MID(D36,FIND("-",D36)+1,FIND("-",D36,FIND("-",D36)+1)-FIND("-",D36)-1)),0)+IFERROR(VALUE(MID(E36,FIND("-",E36)+1,FIND("-",E36,FIND("-",E36)+1)-FIND("-",E36)-1)),0)+IFERROR(VALUE(MID(F36,FIND("-",F36)+1,FIND("-",F36,FIND("-",F36)+1)-FIND("-",F36)-1)),0)+IFERROR(VALUE(MID(G36,FIND("-",G36)+1,FIND("-",G36,FIND("-",G36)+1)-FIND("-",G36)-1)),0)+IFERROR(VALUE(MID(H36,FIND("-",H36)+1,FIND("-",H36,FIND("-",H36)+1)-FIND("-",H36)-1)),0)+IFERROR(VALUE(MID(I36,FIND("-",I36)+1,FIND("-",I36,FIND("-",I36)+1)-FIND("-",I36)-1)),0)+IFERROR(VALUE(MID(J36,FIND("-",J36)+1,FIND("-",J36,FIND("-",J36)+1)-FIND("-",J36)-1)),0) -> 72 | L36: =IF(ROW()-33>$C$5,"— unused —",IF(K36=0,"empty",IF(K36=$C$6,"OK 72",IF(K36>$C$6,"OVER "&K36,"SHORT "&($C$6-K36))))) -> OK 72
A37: R4 | B37: 2x6-16-2 | C37: 2x8-14-MSR | D37: 2x8-14-MSR | E37: 2x8-14-MSR | F37: 2x8-14-MSR | K37: =IFERROR(VALUE(MID(B37,FIND("-",B37)+1,FIND("-",B37,FIND("-",B37)+1)-FIND("-",B37)-1)),0)+IFERROR(VALUE(MID(C37,FIND("-",C37)+1,FIND("-",C37,FIND("-",C37)+1)-FIND("-",C37)-1)),0)+IFERROR(VALUE(MID(D37,FIND("-",D37)+1,FIND("-",D37,FIND("-",D37)+1)-FIND("-",D37)-1)),0)+IFERROR(VALUE(MID(E37,FIND("-",E37)+1,FIND("-",E37,FIND("-",E37)+1)-FIND("-",E37)-1)),0)+IFERROR(VALUE(MID(F37,FIND("-",F37)+1,FIND("-",F37,FIND("-",F37)+1)-FIND("-",F37)-1)),0)+IFERROR(VALUE(MID(G37,FIND("-",G37)+1,FIND("-",G37,FIND("-",G37)+1)-FIND("-",G37)-1)),0)+IFERROR(VALUE(MID(H37,FIND("-",H37)+1,FIND("-",H37,FIND("-",H37)+1)-FIND("-",H37)-1)),0)+IFERROR(VALUE(MID(I37,FIND("-",I37)+1,FIND("-",I37,FIND("-",I37)+1)-FIND("-",I37)-1)),0)+IFERROR(VALUE(MID(J37,FIND("-",J37)+1,FIND("-",J37,FIND("-",J37)+1)-FIND("-",J37)-1)),0) -> 72 | L37: =IF(ROW()-33>$C$5,"— unused —",IF(K37=0,"empty",IF(K37=$C$6,"OK 72",IF(K37>$C$6,"OVER "&K37,"SHORT "&($C$6-K37))))) -> OK 72
A38: R5 | B38: 2x6-16-2 | C38: 2x8-14-MSR | D38: 2x8-14-MSR | E38: 2x8-14-MSR | F38: 2x8-14-MSR | K38: =IFERROR(VALUE(MID(B38,FIND("-",B38)+1,FIND("-",B38,FIND("-",B38)+1)-FIND("-",B38)-1)),0)+IFERROR(VALUE(MID(C38,FIND("-",C38)+1,FIND("-",C38,FIND("-",C38)+1)-FIND("-",C38)-1)),0)+IFERROR(VALUE(MID(D38,FIND("-",D38)+1,FIND("-",D38,FIND("-",D38)+1)-FIND("-",D38)-1)),0)+IFERROR(VALUE(MID(E38,FIND("-",E38)+1,FIND("-",E38,FIND("-",E38)+1)-FIND("-",E38)-1)),0)+IFERROR(VALUE(MID(F38,FIND("-",F38)+1,FIND("-",F38,FIND("-",F38)+1)-FIND("-",F38)-1)),0)+IFERROR(VALUE(MID(G38,FIND("-",G38)+1,FIND("-",G38,FIND("-",G38)+1)-FIND("-",G38)-1)),0)+IFERROR(VALUE(MID(H38,FIND("-",H38)+1,FIND("-",H38,FIND("-",H38)+1)-FIND("-",H38)-1)),0)+IFERROR(VALUE(MID(I38,FIND("-",I38)+1,FIND("-",I38,FIND("-",I38)+1)-FIND("-",I38)-1)),0)+IFERROR(VALUE(MID(J38,FIND("-",J38)+1,FIND("-",J38,FIND("-",J38)+1)-FIND("-",J38)-1)),0) -> 72 | L38: =IF(ROW()-33>$C$5,"— unused —",IF(K38=0,"empty",IF(K38=$C$6,"OK 72",IF(K38>$C$6,"OVER "&K38,"SHORT "&($C$6-K38))))) -> OK 72
A39: R6 | B39: 2x4-12-1 | C39: 2x4-12-1 | D39: 2x4-12-1 | E39: 2x4-12-1 | F39: 2x4-12-1 | G39: 2x4-12-1 | K39: =IFERROR(VALUE(MID(B39,FIND("-",B39)+1,FIND("-",B39,FIND("-",B39)+1)-FIND("-",B39)-1)),0)+IFERROR(VALUE(MID(C39,FIND("-",C39)+1,FIND("-",C39,FIND("-",C39)+1)-FIND("-",C39)-1)),0)+IFERROR(VALUE(MID(D39,FIND("-",D39)+1,FIND("-",D39,FIND("-",D39)+1)-FIND("-",D39)-1)),0)+IFERROR(VALUE(MID(E39,FIND("-",E39)+1,FIND("-",E39,FIND("-",E39)+1)-FIND("-",E39)-1)),0)+IFERROR(VALUE(MID(F39,FIND("-",F39)+1,FIND("-",F39,FIND("-",F39)+1)-FIND("-",F39)-1)),0)+IFERROR(VALUE(MID(G39,FIND("-",G39)+1,FIND("-",G39,FIND("-",G39)+1)-FIND("-",G39)-1)),0)+IFERROR(VALUE(MID(H39,FIND("-",H39)+1,FIND("-",H39,FIND("-",H39)+1)-FIND("-",H39)-1)),0)+IFERROR(VALUE(MID(I39,FIND("-",I39)+1,FIND("-",I39,FIND("-",I39)+1)-FIND("-",I39)-1)),0)+IFERROR(VALUE(MID(J39,FIND("-",J39)+1,FIND("-",J39,FIND("-",J39)+1)-FIND("-",J39)-1)),0) -> 72 | L39: =IF(ROW()-33>$C$5,"— unused —",IF(K39=0,"empty",IF(K39=$C$6,"OK 72",IF(K39>$C$6,"OVER "&K39,"SHORT "&($C$6-K39))))) -> OK 72
A40: R7 | B40: 2x4-12-1 | C40: 2x4-12-1 | D40: 2x4-12-1 | E40: 2x4-12-1 | F40: 2x4-12-1 | G40: 2x4-12-1 | K40: =IFERROR(VALUE(MID(B40,FIND("-",B40)+1,FIND("-",B40,FIND("-",B40)+1)-FIND("-",B40)-1)),0)+IFERROR(VALUE(MID(C40,FIND("-",C40)+1,FIND("-",C40,FIND("-",C40)+1)-FIND("-",C40)-1)),0)+IFERROR(VALUE(MID(D40,FIND("-",D40)+1,FIND("-",D40,FIND("-",D40)+1)-FIND("-",D40)-1)),0)+IFERROR(VALUE(MID(E40,FIND("-",E40)+1,FIND("-",E40,FIND("-",E40)+1)-FIND("-",E40)-1)),0)+IFERROR(VALUE(MID(F40,FIND("-",F40)+1,FIND("-",F40,FIND("-",F40)+1)-FIND("-",F40)-1)),0)+IFERROR(VALUE(MID(G40,FIND("-",G40)+1,FIND("-",G40,FIND("-",G40)+1)-FIND("-",G40)-1)),0)+IFERROR(VALUE(MID(H40,FIND("-",H40)+1,FIND("-",H40,FIND("-",H40)+1)-FIND("-",H40)-1)),0)+IFERROR(VALUE(MID(I40,FIND("-",I40)+1,FIND("-",I40,FIND("-",I40)+1)-FIND("-",I40)-1)),0)+IFERROR(VALUE(MID(J40,FIND("-",J40)+1,FIND("-",J40,FIND("-",J40)+1)-FIND("-",J40)-1)),0) -> 72 | L40: =IF(ROW()-33>$C$5,"— unused —",IF(K40=0,"empty",IF(K40=$C$6,"OK 72",IF(K40>$C$6,"OVER "&K40,"SHORT "&($C$6-K40))))) -> OK 72
A41: R8 | B41: 2x4-12-1 | C41: 2x4-12-1 | D41: 2x4-12-1 | E41: 2x4-12-1 | F41: 2x4-12-1 | G41: 2x4-12-1 | K41: =IFERROR(VALUE(MID(B41,FIND("-",B41)+1,FIND("-",B41,FIND("-",B41)+1)-FIND("-",B41)-1)),0)+IFERROR(VALUE(MID(C41,FIND("-",C41)+1,FIND("-",C41,FIND("-",C41)+1)-FIND("-",C41)-1)),0)+IFERROR(VALUE(MID(D41,FIND("-",D41)+1,FIND("-",D41,FIND("-",D41)+1)-FIND("-",D41)-1)),0)+IFERROR(VALUE(MID(E41,FIND("-",E41)+1,FIND("-",E41,FIND("-",E41)+1)-FIND("-",E41)-1)),0)+IFERROR(VALUE(MID(F41,FIND("-",F41)+1,FIND("-",F41,FIND("-",F41)+1)-FIND("-",F41)-1)),0)+IFERROR(VALUE(MID(G41,FIND("-",G41)+1,FIND("-",G41,FIND("-",G41)+1)-FIND("-",G41)-1)),0)+IFERROR(VALUE(MID(H41,FIND("-",H41)+1,FIND("-",H41,FIND("-",H41)+1)-FIND("-",H41)-1)),0)+IFERROR(VALUE(MID(I41,FIND("-",I41)+1,FIND("-",I41,FIND("-",I41)+1)-FIND("-",I41)-1)),0)+IFERROR(VALUE(MID(J41,FIND("-",J41)+1,FIND("-",J41,FIND("-",J41)+1)-FIND("-",J41)-1)),0) -> 72 | L41: =IF(ROW()-33>$C$5,"— unused —",IF(K41=0,"empty",IF(K41=$C$6,"OK 72",IF(K41>$C$6,"OVER "&K41,"SHORT "&($C$6-K41))))) -> OK 72
A42: R9 | B42: 2x4-12-1 | C42: 2x4-12-1 | D42: 2x4-12-1 | E42: 2x4-12-1 | F42: 2x4-12-1 | G42: 2x4-12-1 | K42: =IFERROR(VALUE(MID(B42,FIND("-",B42)+1,FIND("-",B42,FIND("-",B42)+1)-FIND("-",B42)-1)),0)+IFERROR(VALUE(MID(C42,FIND("-",C42)+1,FIND("-",C42,FIND("-",C42)+1)-FIND("-",C42)-1)),0)+IFERROR(VALUE(MID(D42,FIND("-",D42)+1,FIND("-",D42,FIND("-",D42)+1)-FIND("-",D42)-1)),0)+IFERROR(VALUE(MID(E42,FIND("-",E42)+1,FIND("-",E42,FIND("-",E42)+1)-FIND("-",E42)-1)),0)+IFERROR(VALUE(MID(F42,FIND("-",F42)+1,FIND("-",F42,FIND("-",F42)+1)-FIND("-",F42)-1)),0)+IFERROR(VALUE(MID(G42,FIND("-",G42)+1,FIND("-",G42,FIND("-",G42)+1)-FIND("-",G42)-1)),0)+IFERROR(VALUE(MID(H42,FIND("-",H42)+1,FIND("-",H42,FIND("-",H42)+1)-FIND("-",H42)-1)),0)+IFERROR(VALUE(MID(I42,FIND("-",I42)+1,FIND("-",I42,FIND("-",I42)+1)-FIND("-",I42)-1)),0)+IFERROR(VALUE(MID(J42,FIND("-",J42)+1,FIND("-",J42,FIND("-",J42)+1)-FIND("-",J42)-1)),0) -> 72 | L42: =IF(ROW()-33>$C$5,"— unused —",IF(K42=0,"empty",IF(K42=$C$6,"OK 72",IF(K42>$C$6,"OVER "&K42,"SHORT "&($C$6-K42))))) -> OK 72
A43: R10 | B43: 2x4-12-1 | C43: 2x4-12-1 | D43: 2x4-12-1 | E43: 2x4-12-1 | F43: 2x4-12-1 | G43: 2x4-12-1 | K43: =IFERROR(VALUE(MID(B43,FIND("-",B43)+1,FIND("-",B43,FIND("-",B43)+1)-FIND("-",B43)-1)),0)+IFERROR(VALUE(MID(C43,FIND("-",C43)+1,FIND("-",C43,FIND("-",C43)+1)-FIND("-",C43)-1)),0)+IFERROR(VALUE(MID(D43,FIND("-",D43)+1,FIND("-",D43,FIND("-",D43)+1)-FIND("-",D43)-1)),0)+IFERROR(VALUE(MID(E43,FIND("-",E43)+1,FIND("-",E43,FIND("-",E43)+1)-FIND("-",E43)-1)),0)+IFERROR(VALUE(MID(F43,FIND("-",F43)+1,FIND("-",F43,FIND("-",F43)+1)-FIND("-",F43)-1)),0)+IFERROR(VALUE(MID(G43,FIND("-",G43)+1,FIND("-",G43,FIND("-",G43)+1)-FIND("-",G43)-1)),0)+IFERROR(VALUE(MID(H43,FIND("-",H43)+1,FIND("-",H43,FIND("-",H43)+1)-FIND("-",H43)-1)),0)+IFERROR(VALUE(MID(I43,FIND("-",I43)+1,FIND("-",I43,FIND("-",I43)+1)-FIND("-",I43)-1)),0)+IFERROR(VALUE(MID(J43,FIND("-",J43)+1,FIND("-",J43,FIND("-",J43)+1)-FIND("-",J43)-1)),0) -> 72 | L43: =IF(ROW()-33>$C$5,"— unused —",IF(K43=0,"empty",IF(K43=$C$6,"OK 72",IF(K43>$C$6,"OVER "&K43,"SHORT "&($C$6-K43))))) -> OK 72
...

Sheet Manifest
A1: LOAD MANIFEST
A2: Car layout mirrors the Planner. Cell FILL = product, BORDER = grade. Differentiated by product, length, and grade below.
A4: Car Type: | B4: Centerbeam 72 ft
A5: Rows: | B5: =Planner!C5 -> 10
A6: Total Lineal Ft: | B6: =Planner!F30 -> 720
A7: Date: | B7: =TODAY() -> 46187
A8: Notes: | B8: (car #, shipper, instructions)
A10: LENGTH (fill): | B10: 8' | C10: 10' | D10: 12' | E10: 14' | F10: 16' | G10: 18' | H10: 20'
A11: PRODUCT (border): | B11: 2x4 | C11: 2x6 | D11: 2x8 | E11: 2x10 | F11: 4x4 | G11: 4x6 | H11: 6x6
A12: GRADE (text): | B12: 1 | C12: 2 | D12: 3 | E12: 4 | F12: 2P | G12: MSR
A13: CAR LAYOUT (as loaded) — each row = 72 ft, loaded left→right from the center beam
A14: Row | B14: P1 | C14: P2 | D14: P3 | E14: P4 | F14: P5 | G14: P6 | H14: P7 | I14: P8 | J14: P9 | K14: Total | L14: Status
A15: R1 | B15: =IF(Planner!B34="","",Planner!B34) -> 2x4-16-2 | C15: =IF(Planner!C34="","",Planner!C34) -> 2x6-14-2 | D15: =IF(Planner!D34="","",Planner!D34) -> 2x6-14-2 | E15: =IF(Planner!E34="","",Planner!E34) -> 2x6-14-2 | F15: =IF(Planner!F34="","",Planner!F34) -> 2x6-14-2 | G15: =IF(Planner!G34="","",Planner!G34) | H15: =IF(Planner!H34="","",Planner!H34) | I15: =IF(Planner!I34="","",Planner!I34) | J15: =IF(Planner!J34="","",Planner!J34) | K15: =IF(Planner!K34=0,"",Planner!K34) -> 72 | L15: =Planner!L34 -> OK 72
A16: R2 | B16: =IF(Planner!B35="","",Planner!B35) -> 2x4-16-2 | C16: =IF(Planner!C35="","",Planner!C35) -> 2x6-14-2 | D16: =IF(Planner!D35="","",Planner!D35) -> 2x6-14-2 | E16: =IF(Planner!E35="","",Planner!E35) -> 2x6-14-2 | F16: =IF(Planner!F35="","",Planner!F35) -> 2x6-14-2 | G16: =IF(Planner!G35="","",Planner!G35) | H16: =IF(Planner!H35="","",Planner!H35) | I16: =IF(Planner!I35="","",Planner!I35) | J16: =IF(Planner!J35="","",Planner!J35) | K16: =IF(Planner!K35=0,"",Planner!K35) -> 72 | L16: =Planner!L35 -> OK 72
A17: R3 | B17: =IF(Planner!B36="","",Planner!B36) -> 2x6-16-2 | C17: =IF(Planner!C36="","",Planner!C36) -> 2x6-14-2 | D17: =IF(Planner!D36="","",Planner!D36) -> 2x6-14-2 | E17: =IF(Planner!E36="","",Planner!E36) -> 2x6-14-2 | F17: =IF(Planner!F36="","",Planner!F36) -> 2x6-14-2 | G17: =IF(Planner!G36="","",Planner!G36) | H17: =IF(Planner!H36="","",Planner!H36) | I17: =IF(Planner!I36="","",Planner!I36) | J17: =IF(Planner!J36="","",Planner!J36) | K17: =IF(Planner!K36=0,"",Planner!K36) -> 72 | L17: =Planner!L36 -> OK 72
A18: R4 | B18: =IF(Planner!B37="","",Planner!B37) -> 2x6-16-2 | C18: =IF(Planner!C37="","",Planner!C37) -> 2x8-14-MSR | D18: =IF(Planner!D37="","",Planner!D37) -> 2x8-14-MSR | E18: =IF(Planner!E37="","",Planner!E37) -> 2x8-14-MSR | F18: =IF(Planner!F37="","",Planner!F37) -> 2x8-14-MSR | G18: =IF(Planner!G37="","",Planner!G37) | H18: =IF(Planner!H37="","",Planner!H37) | I18: =IF(Planner!I37="","",Planner!I37) | J18: =IF(Planner!J37="","",Planner!J37) | K18: =IF(Planner!K37=0,"",Planner!K37) -> 72 | L18: =Planner!L37 -> OK 72
A19: R5 | B19: =IF(Planner!B38="","",Planner!B38) -> 2x6-16-2 | C19: =IF(Planner!C38="","",Planner!C38) -> 2x8-14-MSR | D19: =IF(Planner!D38="","",Planner!D38) -> 2x8-14-MSR | E19: =IF(Planner!E38="","",Planner!E38) -> 2x8-14-MSR | F19: =IF(Planner!F38="","",Planner!F38) -> 2x8-14-MSR | G19: =IF(Planner!G38="","",Planner!G38) | H19: =IF(Planner!H38="","",Planner!H38) | I19: =IF(Planner!I38="","",Planner!I38) | J19: =IF(Planner!J38="","",Planner!J38) | K19: =IF(Planner!K38=0,"",Planner!K38) -> 72 | L19: =Planner!L38 -> OK 72
A20: R6 | B20: =IF(Planner!B39="","",Planner!B39) -> 2x4-12-1 | C20: =IF(Planner!C39="","",Planner!C39) -> 2x4-12-1 | D20: =IF(Planner!D39="","",Planner!D39) -> 2x4-12-1 | E20: =IF(Planner!E39="","",Planner!E39) -> 2x4-12-1 | F20: =IF(Planner!F39="","",Planner!F39) -> 2x4-12-1 | G20: =IF(Planner!G39="","",Planner!G39) -> 2x4-12-1 | H20: =IF(Planner!H39="","",Planner!H39) | I20: =IF(Planner!I39="","",Planner!I39) | J20: =IF(Planner!J39="","",Planner!J39) | K20: =IF(Planner!K39=0,"",Planner!K39) -> 72 | L20: =Planner!L39 -> OK 72
A21: R7 | B21: =IF(Planner!B40="","",Planner!B40) -> 2x4-12-1 | C21: =IF(Planner!C40="","",Planner!C40) -> 2x4-12-1 | D21: =IF(Planner!D40="","",Planner!D40) -> 2x4-12-1 | E21: =IF(Planner!E40="","",Planner!E40) -> 2x4-12-1 | F21: =IF(Planner!F40="","",Planner!F40) -> 2x4-12-1 | G21: =IF(Planner!G40="","",Planner!G40) -> 2x4-12-1 | H21: =IF(Planner!H40="","",Planner!H40) | I21: =IF(Planner!I40="","",Planner!I40) | J21: =IF(Planner!J40="","",Planner!J40) | K21: =IF(Planner!K40=0,"",Planner!K40) -> 72 | L21: =Planner!L40 -> OK 72
A22: R8 | B22: =IF(Planner!B41="","",Planner!B41) -> 2x4-12-1 | C22: =IF(Planner!C41="","",Planner!C41) -> 2x4-12-1 | D22: =IF(Planner!D41="","",Planner!D41) -> 2x4-12-1 | E22: =IF(Planner!E41="","",Planner!E41) -> 2x4-12-1 | F22: =IF(Planner!F41="","",Planner!F41) -> 2x4-12-1 | G22: =IF(Planner!G41="","",Planner!G41) -> 2x4-12-1 | H22: =IF(Planner!H41="","",Planner!H41) | I22: =IF(Planner!I41="","",Planner!I41) | J22: =IF(Planner!J41="","",Planner!J41) | K22: =IF(Planner!K41=0,"",Planner!K41) -> 72 | L22: =Planner!L41 -> OK 72
A23: R9 | B23: =IF(Planner!B42="","",Planner!B42) -> 2x4-12-1 | C23: =IF(Planner!C42="","",Planner!C42) -> 2x4-12-1 | D23: =IF(Planner!D42="","",Planner!D42) -> 2x4-12-1 | E23: =IF(Planner!E42="","",Planner!E42) -> 2x4-12-1 | F23: =IF(Planner!F42="","",Planner!F42) -> 2x4-12-1 | G23: =IF(Planner!G42="","",Planner!G42) -> 2x4-12-1 | H23: =IF(Planner!H42="","",Planner!H42) | I23: =IF(Planner!I42="","",Planner!I42) | J23: =IF(Planner!J42="","",Planner!J42) | K23: =IF(Planner!K42=0,"",Planner!K42) -> 72 | L23: =Planner!L42 -> OK 72
A24: R10 | B24: =IF(Planner!B43="","",Planner!B43) -> 2x4-12-1 | C24: =IF(Planner!C43="","",Planner!C43) -> 2x4-12-1 | D24: =IF(Planner!D43="","",Planner!D43) -> 2x4-12-1 | E24: =IF(Planner!E43="","",Planner!E43) -> 2x4-12-1 | F24: =IF(Planner!F43="","",Planner!F43) -> 2x4-12-1 | G24: =IF(Planner!G43="","",Planner!G43) -> 2x4-12-1 | H24: =IF(Planner!H43="","",Planner!H43) | I24: =IF(Planner!I43="","",Planner!I43) | J24: =IF(Planner!J43="","",Planner!J43) | K24: =IF(Planner!K43=0,"",Planner!K43) -> 72 | L24: =Planner!L43 -> OK 72
A25: R11 | B25: =IF(Planner!B44="","",Planner!B44) | C25: =IF(Planner!C44="","",Planner!C44) | D25: =IF(Planner!D44="","",Planner!D44) | E25: =IF(Planner!E44="","",Planner!E44) | F25: =IF(Planner!F44="","",Planner!F44) | G25: =IF(Planner!G44="","",Planner!G44) | H25: =IF(Planner!H44="","",Planner!H44) | I25: =IF(Planner!I44="","",Planner!I44) | J25: =IF(Planner!J44="","",Planner!J44) | K25: =IF(Planner!K44=0,"",Planner!K44) | L25: =Planner!L44 -> — unused —
A26: R12 | B26: =IF(Planner!B45="","",Planner!B45) | C26: =IF(Planner!C45="","",Planner!C45) | D26: =IF(Planner!D45="","",Planner!D45) | E26: =IF(Planner!E45="","",Planner!E45) | F26: =IF(Planner!F45="","",Planner!F45) | G26: =IF(Planner!G45="","",Planner!G45) | H26: =IF(Planner!H45="","",Planner!H45) | I26: =IF(Planner!I45="","",Planner!I45) | J26: =IF(Planner!J45="","",Planner!J45) | K26: =IF(Planner!K45=0,"",Planner!K45) | L26: =Planner!L45 -> — unused —
... A28: R14 | B28: =IF(Planner!B47="","",Planner!B47) | C28: =IF(Planner!C47="","",Planner!C47) | D28: =IF(Planner!D47="","",Planner!D47) | E28: =IF(Planner!E47="","",Planner!E47) | F28: =IF(Planner!F47="","",Planner!F47) | G28: =IF(Planner!G47="","",Planner!G47) | H28: =IF(Planner!H47="","",Planner!H47) | I28: =IF(Planner!I47="","",Planner!I47) | J28: =IF(Planner!J47="","",Planner!J47) | K28: =IF(Planner!K47=0,"",Planner!K47) | L28: =Planner!L47 -> — unused —
A30: SUMMARY BY PRODUCT | E30: SUMMARY BY GRADE
A31: Product | B31: Placed Packs | C31: Lineal Ft | E31: Grade | F31: Placed Packs | G31: Lineal Ft
A32: 2x4 | B32: =SUMIF(Planner!$B$10:$B$29,"2x4",Planner!$G$10:$G$29) -> 32 | C32: =SUMIF(Planner!$B$10:$B$29,"2x4",Planner!$I$10:$I$29) -> 392 | E32: 1 | F32: =SUMIF(Planner!$D$10:$D$29,"1",Planner!$G$10:$G$29) -> 30 | G32: =SUMIF(Planner!$D$10:$D$29,"1",Planner!$I$10:$I$29) -> 360
A33: 2x6 | B33: =SUMIF(Planner!$B$10:$B$29,"2x6",Planner!$G$10:$G$29) -> 15 | C33: =SUMIF(Planner!$B$10:$B$29,"2x6",Planner!$I$10:$I$29) -> 216 | E33: 2 | F33: =SUMIF(Planner!$D$10:$D$29,"2",Planner!$G$10:$G$29) -> 17 | G33: =SUMIF(Planner!$D$10:$D$29,"2",Planner!$I$10:$I$29) -> 248
A34: 2x8 | B34: =SUMIF(Planner!$B$10:$B$29,"2x8",Planner!$G$10:$G$29) -> 8 | C34: =SUMIF(Planner!$B$10:$B$29,"2x8",Planner!$I$10:$I$29) -> 112 | E34: 3 | F34: =SUMIF(Planner!$D$10:$D$29,"3",Planner!$G$10:$G$29) -> 0 | G34: =SUMIF(Planner!$D$10:$D$29,"3",Planner!$I$10:$I$29) -> 0
A35: 2x10 | B35: =SUMIF(Planner!$B$10:$B$29,"2x10",Planner!$G$10:$G$29) -> 0 | C35: =SUMIF(Planner!$B$10:$B$29,"2x10",Planner!$I$10:$I$29) -> 0 | E35: 4 | F35: =SUMIF(Planner!$D$10:$D$29,"4",Planner!$G$10:$G$29) -> 0 | G35: =SUMIF(Planner!$D$10:$D$29,"4",Planner!$I$10:$I$29) -> 0
A36: 4x4 | B36: =SUMIF(Planner!$B$10:$B$29,"4x4",Planner!$G$10:$G$29) -> 0 | C36: =SUMIF(Planner!$B$10:$B$29,"4x4",Planner!$I$10:$I$29) -> 0 | E36: 2P | F36: =SUMIF(Planner!$D$10:$D$29,"2P",Planner!$G$10:$G$29) -> 0 | G36: =SUMIF(Planner!$D$10:$D$29,"2P",Planner!$I$10:$I$29) -> 0
A37: 4x6 | B37: =SUMIF(Planner!$B$10:$B$29,"4x6",Planner!$G$10:$G$29) -> 0 | C37: =SUMIF(Planner!$B$10:$B$29,"4x6",Planner!$I$10:$I$29) -> 0 | E37: MSR | F37: =SUMIF(Planner!$D$10:$D$29,"MSR",Planner!$G$10:$G$29) -> 8 | G37: =SUMIF(Planner!$D$10:$D$29,"MSR",Planner!$I$10:$I$29) -> 112
A38: 6x6 | B38: =SUMIF(Planner!$B$10:$B$29,"6x6",Planner!$G$10:$G$29) -> 0 | C38: =SUMIF(Planner!$B$10:$B$29,"6x6",Planner!$I$10:$I$29) -> 0
A40: PLACED PACKS — product × grade
A41: Prod\Grd | B41: 1 | C41: 2 | D41: 3 | E41: 4 | F41: 2P | G41: MSR | H41: Total
A42: 2x4 | B42: =SUMIFS(Planner!$G$10:$G$29,Planner!$B$10:$B$29,"2x4",Planner!$D$10:$D$29,"1") -> 30 | C42: =SUMIFS(Planner!$G$10:$G$29,Planner!$B$10:$B$29,"2x4",Planner!$D$10:$D$29,"2") -> 2 | D42: =SUMIFS(Planner!$G$10:$G$29,Planner!$B$10:$B$29,"2x4",Planner!$D$10:$D$29,"3") -> 0 | E42: =SUMIFS(Planner!$G$10:$G$29,Planner!$B$10:$B$29,"2x4",Planner!$D$10:$D$29,"4") -> 0 | F42: =SUMIFS(Planner!$G$10:$G$29,Planner!$B$10:$B$29,"2x4",Planner!$D$10:$D$29,"2P") -> 0 | G42: =SUMIFS(Planner!$G$10:$G$29,Planner!$B$10:$B$29,"2x4",Planner!$D$10:$D$29,"MSR") -> 0 | H42: =SUM(B42:G42) -> 32
A43: 2x6 | B43: =SUMIFS(Planner!$G$10:$G$29,Planner!$B$10:$B$29,"2x6",Planner!$D$10:$D$29,"1") -> 0 | C43: =SUMIFS(Planner!$G$10:$G$29,Planner!$B$10:$B$29,"2x6",Planner!$D$10:$D$29,"2") -> 15 | D43: =SUMIFS(Planner!$G$10:$G$29,Planner!$B$10:$B$29,"2x6",Planner!$D$10:$D$29,"3") -> 0 | E43: =SUMIFS(Planner!$G$10:$G$29,Planner!$B$10:$B$29,"2x6",Planner!$D$10:$D$29,"4") -> 0 | F43: =SUMIFS(Planner!$G$10:$G$29,Planner!$B$10:$B$29,"2x6",Planner!$D$10:$D$29,"2P") -> 0 | G43: =SUMIFS(Planner!$G$10:$G$29,Planner!$B$10:$B$29,"2x6",Planner!$D$10:$D$29,"MSR") -> 0 | H43: =SUM(B43:G43) -> 15
A44: 2x8 | B44: =SUMIFS(Planner!$G$10:$G$29,Planner!$B$10:$B$29,"2x8",Planner!$D$10:$D$29,"1") -> 0 | C44: =SUMIFS(Planner!$G$10:$G$29,Planner!$B$10:$B$29,"2x8",Planner!$D$10:$D$29,"2") -> 0 | D44: =SUMIFS(Planner!$G$10:$G$29,Planner!$B$10:$B$29,"2x8",Planner!$D$10:$D$29,"3") -> 0 | E44: =SUMIFS(Planner!$G$10:$G$29,Planner!$B$10:$B$29,"2x8",Planner!$D$10:$D$29,"4") -> 0 | F44: =SUMIFS(Planner!$G$10:$G$29,Planner!$B$10:$B$29,"2x8",Planner!$D$10:$D$29,"2P") -> 0 | G44: =SUMIFS(Planner!$G$10:$G$29,Planner!$B$10:$B$29,"2x8",Planner!$D$10:$D$29,"MSR") -> 8 | H44: =SUM(B44:G44) -> 8
A45: 2x10 | B45: =SUMIFS(Planner!$G$10:$G$29,Planner!$B$10:$B$29,"2x10",Planner!$D$10:$D$29,"1") -> 0 | C45: =SUMIFS(Planner!$G$10:$G$29,Planner!$B$10:$B$29,"2x10",Planner!$D$10:$D$29,"2") -> 0 | D45: =SUMIFS(Planner!$G$10:$G$29,Planner!$B$10:$B$29,"2x10",Planner!$D$10:$D$29,"3") -> 0 | E45: =SUMIFS(Planner!$G$10:$G$29,Planner!$B$10:$B$29,"2x10",Planner!$D$10:$D$29,"4") -> 0 | F45: =SUMIFS(Planner!$G$10:$G$29,Planner!$B$10:$B$29,"2x10",Planner!$D$10:$D$29,"2P") -> 0 | G45: =SUMIFS(Planner!$G$10:$G$29,Planner!$B$10:$B$29,"2x10",Planner!$D$10:$D$29,"MSR") -> 0 | H45: =SUM(B45:G45) -> 0
...

Sheet Pattern Library
A1: VALID 72-FT LENGTH PATTERNS
A2: Every length combination summing to 72 ft, color-coded by length. The 72-ft fit depends only on lengths; product & grade ride along on each pack.
A4: # | B4: Lengths (ft) | C4: 8' | D4: 10' | E4: 12' | F4: 14' | G4: 16' | H4: 18' | I4: 20' | J4: Total
A5: 1 | B5: 20 20 20 12 | E5: 1 | I5: 3 | J5: 72
A6: 2 | B6: 20 20 18 14 | F6: 1 | H6: 1 | I6: 2 | J6: 72
A7: 3 | B7: 20 20 16 16 | G7: 2 | I7: 2 | J7: 72
A8: 4 | B8: 20 18 18 16 | G8: 1 | H8: 2 | I8: 1 | J8: 72
A9: 5 | B9: 18 18 18 18 | H9: 4 | J9: 72
A10: 6 | B10: 20 20 16 8 8 | C10: 2 | G10: 1 | I10: 2 | J10: 72
A11: 7 | B11: 20 20 14 10 8 | C11: 1 | D11: 1 | F11: 1 | I11: 2 | J11: 72
A12: 8 | B12: 20 20 12 12 8 | C12: 1 | E12: 2 | I12: 2 | J12: 72
A13: 9 | B13: 20 20 12 10 10 | D13: 2 | E13: 1 | I13: 2 | J13: 72
A14: 10 | B14: 20 18 18 8 8 | C14: 2 | H14: 2 | I14: 1 | J14: 72
A15: 11 | B15: 20 18 16 10 8 | C15: 1 | D15: 1 | G15: 1 | H15: 1 | I15: 1 | J15: 72
A16: 12 | B16: 20 18 14 12 8 | C16: 1 | E16: 1 | F16: 1 | H16: 1 | I16: 1 | J16: 72
A17: 13 | B17: 20 18 14 10 10 | D17: 2 | F17: 1 | H17: 1 | I17: 1 | J17: 72
A18: 14 | B18: 20 18 12 12 10 | D18: 1 | E18: 2 | H18: 1 | I18: 1 | J18: 72
A19: 15 | B19: 20 16 16 12 8 | C19: 1 | E19: 1 | G19: 2 | I19: 1 | J19: 72
A20: 16 | B20: 20 16 16 10 10 | D20: 2 | G20: 2 | I20: 1 | J20: 72
A21: 17 | B21: 20 16 14 14 8 | C21: 1 | F21: 2 | G21: 1 | I21: 1 | J21: 72
A22: 18 | B22: 20 16 14 12 10 | D22: 1 | E22: 1 | F22: 1 | G22: 1 | I22: 1 | J22: 72
A23: 19 | B23: 20 16 12 12 12 | E23: 3 | G23: 1 | I23: 1 | J23: 72
A24: 20 | B24: 20 14 14 14 10 | D24: 1 | F24: 3 | I24: 1 | J24: 72
A25: 21 | B25: 20 14 14 12 12 | E25: 2 | F25: 2 | I25: 1 | J25: 72
A26: 22 | B26: 18 18 18 10 8 | C26: 1 | D26: 1 | H26: 3 | J26: 72
A27: 23 | B27: 18 18 16 12 8 | C27: 1 | E27: 1 | G27: 1 | H27: 2 | J27: 72
A28: 24 | B28: 18 18 16 10 10 | D28: 2 | G28: 1 | H28: 2 | J28: 72
A29: 25 | B29: 18 18 14 14 8 | C29: 1 | F29: 2 | H29: 2 | J29: 72
A30: 26 | B30: 18 18 14 12 10 | D30: 1 | E30: 1 | F30: 1 | H30: 2 | J30: 72
A31: 27 | B31: 18 18 12 12 12 | E31: 3 | H31: 2 | J31: 72
A32: 28 | B32: 18 16 16 14 8 | C32: 1 | F32: 1 | G32: 2 | H32: 1 | J32: 72
A33: 29 | B33: 18 16 16 12 10 | D33: 1 | E33: 1 | G33: 2 | H33: 1 | J33: 72
A34: 30 | B34: 18 16 14 14 10 | D34: 1 | F34: 2 | G34: 1 | H34: 1 | J34: 72
A35: 31 | B35: 18 16 14 12 12 | E35: 2 | F35: 1 | G35: 1 | H35: 1 | J35: 72
A36: 32 | B36: 18 14 14 14 12 | E36: 1 | F36: 3 | H36: 1 | J36: 72
A37: 33 | B37: 16 16 16 16 8 | C37: 1 | G37: 4 | J37: 72
A38: 34 | B38: 16 16 16 14 10 | D38: 1 | F38: 1 | G38: 3 | J38: 72
A39: 35 | B39: 16 16 16 12 12 | E39: 2 | G39: 3 | J39: 72
A40: 36 | B40: 16 16 14 14 12 | E40: 1 | F40: 2 | G40: 2 | J40: 72
A41: 37 | B41: 16 14 14 14 14 | F41: 4 | G41: 1 | J41: 72
...

Sheet Auto-Solve (VBA)
A1: OPTIONAL: ONE-CLICK AUTO-SOLVER (VBA MACRO)
A4: The Planner works WITHOUT macros (a solved example is loaded). For one-click solving:
A5: 1. Save As ▸ Excel Macro-Enabled Workbook (*.xlsm).
A6: 2. Alt+F11 ▸ File ▸ Import File ▸ CenterbeamSolver.bas (or Insert ▸ Module and paste the code below).
A7: 3. Developer ▸ Insert ▸ Button (Form Control); assign 'SolveLayout'. Add a 2nd button ▸ 'ClearAll'.
A8: 4. SOLVE reads the line-item inventory, fills every selected row to 72 ft, and assigns product+grade
A9: grouped so like packs stack in columns. CLEAR resets the grid + line items. ClearGrid clears grid only.
A11: Cell fill = product, border = grade (see legends on the Planner & Manifest).
A13: ────────────────────── VBA CODE — copy everything below ──────────────────────
A15: Option Explicit
A16: ' === Centerbeam 72-ft Auto-Solver (product + length + grade) ===
A17: Private Patterns As Collection
... A290: End Sub
